Workbook

Sheet SB
B6: Cristobal | C6: Martha | D6: Leo | E6: ANUALIDAD | G6: DISPONIBLE | I6: PROTECCION | K6: UDIS
E7: udis | F7: pesos | G7: udis | H7: pesos | I7: udis | J7: Pesos | M7: Entrega Mensual | O7: Entrega Anual
B8: 41 | C8: 51 | D8: 10 | E8: 4707 | F8: =E8*K8 -> 38832.75 | G8: 0 | I8: 30000 | J8: =I8*K8 -> 247500 | K8: 8.25 | M8: udis | N8: pesos | O8: udis | P8: pesos
B9: =B8+1 -> 42 | C9: =C8+1 -> 52 | D9: =D8+1 -> 11 | E9: =E8 -> 4707 | F9: =E9*K9 -> 40580.224 | G9: 0 | I9: =I8 -> 30000 | J9: =I9*K9 -> 258637.5 | K9: =K8*1.045 -> 8.62125 | M9: 637 | N9: =(K14*1.045)*M9 -> 7151.6691 | O9: =M9*12 -> 7644 | P9: =N9*12 -> 85820.03
B10: =B9+1 -> 43 | C10: =C9+1 -> 53 | D10: =D9+1 -> 12 | E10: =E9 -> 4707 | F10: =E10*K10 -> 42406.334 | G10: 3879 | H10: =G10*K10 -> 34946.711 | I10: =I9 -> 30000 | J10: =I10*K10 -> 270276.19 | K10: =K9*1.045 -> 9.0092063 | M10: =M9 -> 637 | N10: =(K15*1.045)*M10 -> 7473.4942 | O10: =M10*12 -> 7644 | P10: =N10*12 -> 89681.931
B11: =B10+1 -> 44 | C11: =C10+1 -> 54 | D11: =D10+1 -> 13 | E11: =E10 -> 4707 | F11: =E11*K11 -> 44314.619 | G11: 6111 | H11: =G11*K11 -> 57532.746 | I11: =I10 -> 30000 | J11: =I11*K11 -> 282438.62 | K11: =K10*1.045 -> 9.4146205 | M11: =M10 -> 637 | N11: =(K16*1.045)*M11 -> 7809.8015 | O11: =M11*12 -> 7644 | P11: =N11*12 -> 93717.618
B12: =B11+1 -> 45 | C12: =C11+1 -> 55 | D12: =D11+1 -> 14 | E12: =E11 -> 4707 | F12: =E12*K12 -> 46308.777 | G12: 9057 | H12: =G12*K12 -> 89105.288 | I12: =I11 -> 30000 | J12: =I12*K12 -> 295148.35 | K12: =K11*1.045 -> 9.8382785 | M12: =M11 -> 637 | N12: =(K17*1.045)*M12 -> 8161.2426 | O12: =M12*12 -> 7644 | P12: =N12*12 -> 97934.911
B13: =B12+1 -> 46 | C13: =C12+1 -> 56 | D13: =D12+1 -> 15 | E13: =E12 -> 4707 | F13: =E13*K13 -> 48392.672 | G13: 12642 | H13: =G13*K13 -> 129972.41 | I13: =I12 -> 30000 | J13: =I13*K13 -> 308430.03 | K13: =K12*1.045 -> 10.281001 | P13: =SUM(P9:P12) -> 367154.49
B14: =B13+1 -> 47 | C14: =C13+1 -> 57 | D14: =D13+1 -> 16 | E14: =E13 -> 4707 | F14: =E14*K14 -> 50570.342 | G14: 16848 | H14: =G14*K14 -> 181008.95 | I14: =I13 -> 30000 | J14: =I14*K14 -> 322309.38 | K14: =K13*1.045 -> 10.743646
B15: =B14+1 -> 48 | C15: =C14+1 -> 58 | D15: =D14+1 -> 17 | E15: =E14 -> 4707 | F15: =E15*K15 -> 52846.007 | G15: 30000 | H15: =G15*K15 -> 336813.3 | I15: =I14 -> 30000 | J15: =I15*K15 -> 336813.3 | K15: =K14*1.045 -> 11.22711
K16: =K15*1.045 -> 11.73233
K17: =K16*1.045 -> 12.260285
K18: =K17*1.045 -> 12.811998
K19: =K18*1.045 -> 13.388538
K20: =K19*1.045 -> 13.991022
K21: =K20*1.045 -> 14.620618
K22: =K21*1.045 -> 15.278546
K23: =K22*1.045 -> 15.96608
K24: =K23*1.045 -> 16.684554
K25: =K24*1.045 -> 17.435359
F26: =SUM(F8:F25) -> 364251.72 | H26: =H15 -> 336813.3
M33: EXENCIÓN DE PAGOS DE PRIMAS POR INVALIDEZ

Sheet VM
B1: Lariza
B2: Te presento la estrategia de ahorro y beneficios especiales
B4: Invalidez | D4: 35000 | E4: UDIS | F4: =D4*L9 -> 309050 | G4: =D4*8.32 -> 291200
B5: Fallecimiento | D5: 35000 | E5: UDIS | F5: =D5*L9 -> 309050
C7: AHORRO ANUAL | E7: AVE | H7: ADELANTOS | J7: PROTECCION | L7: UDI
C8: udi | D8: pesos | E8: udi | F8: pesos | H8: udi | I8: pesos | J8: udi | K8: pesos
A9: 1 | B9: 23 | C9: 2217 | D9: =C9*L9 -> 19576.11 | F9: =E9*L9 -> 0 | G9: =F9+D9 -> 19576.11 | I9: 0 | J9: 35000 | K9: =J9*L9 -> 309050 | L9: 8.83
A10: 2 | B10: =B9+1 -> 24 | C10: =C9 -> 2217 | D10: =C10*L10 -> 20457.035 | F10: =E10*L10 -> 0 | G10: =F10+D10 -> 20457.035 | I10: 0 | J10: 35000 | K10: =J10*L10 -> 322957.25 | L10: =L9*1.045 -> 9.22735
A11: 3 | B11: =B10+1 -> 25 | C11: =C10 -> 2217 | D11: =C11*L11 -> 21377.602 | F11: =E11*L11 -> 0 | G11: =F11+D11 -> 21377.602 | I11: 0 | J11: 35000 | K11: =J11*L11 -> 337490.33 | L11: =L10*1.045 -> 9.6425807
A12: 4 | B12: =B11+1 -> 26 | C12: =C11 -> 2217 | D12: =C12*L12 -> 22339.594 | F12: =E12*L12 -> 0 | G12: =F12+D12 -> 22339.594 | I12: 0 | J12: 35000 | K12: =J12*L12 -> 352677.39 | L12: =L11*1.045 -> 10.076497 | N12: TABLA DE ENFERMEDADES CUBIERTAS | R12: % de la SA | S12: $
A13: 5 | B13: =B12+1 -> 27 | C13: =C12 -> 2217 | D13: =C13*L13 -> 23344.875 | F13: =E13*L13 -> 0 | G13: =F13+D13 -> 23344.875 | H13: 1750 | I13: =H13*L13 -> 18427.394 | J13: 35000 | K13: =J13*L13 -> 368547.87 | L13: =L12*1.045 -> 10.529939
A14: 6 | B14: =B13+1 -> 28 | C14: =C13 -> 2217 | D14: =C14*L14 -> 24395.395 | F14: =E14*L14 -> 0 | G14: =F14+D14 -> 24395.395 | I14: 0 | J14: 35000 | K14: =J14*L14 -> 385132.53 | L14: =L13*1.045 -> 11.003787 | N14: TUMOR MALIGNO DE LA MAMA | R14: 1 | S14: =R14*$K9 -> 309050
A15: 7 | B15: =B14+1 -> 29 | C15: =C14 -> 2217 | D15: =C15*L15 -> 25493.187 | F15: =E15*L15 -> 0 | G15: =F15+D15 -> 25493.187 | H15: 1750 | I15: =H15*L15 -> 20123.175 | J15: 35000 | K15: =J15*L15 -> 402463.49 | L15: =L14*1.045 -> 11.498957 | N15: TUMOR MALIGNO DE LA MAMA LOCALIZADO | R15: 0.47 | S15: =R15*$K10 -> 151063.64
A16: 8 | B16: =B15+1 -> 30 | C16: =C15 -> 2217 | D16: =C16*L16 -> 26640.381 | F16: =E16*L16 -> 0 | G16: =F16+D16 -> 26640.381 | I16: 0 | J16: 35000 | K16: =J16*L16 -> 420574.35 | L16: =L15*1.045 -> 12.01641 | N16: TUMOR MALIGNO DEL OVARIO | R16: 0.38 | S16: =R16*$K11 -> 127022.02
A17: 9 | B17: =B16+1 -> 31 | C17: =C16 -> 2217 | D17: =C17*L17 -> 27839.198 | F17: =E17*L17 -> 0 | G17: =F17+D17 -> 27839.198 | H17: 1750 | I17: =H17*L17 -> 21975.01 | J17: 35000 | K17: =J17*L17 -> 439500.19 | L17: =L16*1.045 -> 12.557148 | N17: TUMOR MALIGNO DEL UTERO | R17: 0.21 | S17: =R17*$K12 -> 73004.236
A18: 10 | B18: =B17+1 -> 32 | C18: =C17 -> 2217 | D18: =C18*L18 -> 29091.962 | F18: =E18*L18 -> 0 | G18: =F18+D18 -> 29091.962 | I18: 0 | J18: 35000 | K18: =J18*L18 -> 459277.7 | L18: =L17*1.045 -> 13.12222 | N18: TUMOR MALIGNO DEL UTERO LOCALIZADO | R18: 0.12 | S18: =R18*$K13 -> 43385.375
A19: 11 | B19: =B18+1 -> 33 | C19: =C18 -> 2217 | D19: =C19*L19 -> 30401.1 | F19: =E19*L19 -> 0 | G19: =F19+D19 -> 30401.1 | H19: 1750 | I19: =H19*L19 -> 23997.26 | J19: 35000 | K19: =J19*L19 -> 479945.2 | L19: =L18*1.045 -> 13.71272 | N19: TUMOR MALIGNO DE LAS TROMPAS DE FALOPIO | R19: 0.12 | S19: =R19*$K14 -> 45120.79
A20: 12 | B20: =B19+1 -> 34 | C20: =C19 -> 2217 | D20: =C20*L20 -> 31769.15 | F20: =E20*L20 -> 0 | G20: =F20+D20 -> 31769.15 | I20: 0 | J20: 35000 | K20: =J20*L20 -> 501542.73 | L20: =L19*1.045 -> 14.329792 | N20: TUMOR BENIGNO DE VAGINA O VULVA | R20: 0.09 | S20: =R20*$K15 -> 35194.216
A21: 13 | B21: =B20+1 -> 35 | C21: =C20 -> 2217 | D21: =C21*L21 -> 33198.761 | F21: =E21*L21 -> 0 | G21: =F21+D21 -> 33198.761 | H21: 1750 | I21: =H21*L21 -> 26205.608 | J21: 35000 | K21: =J21*L21 -> 524112.16 | L21: =L20*1.045 -> 14.974633
A22: 14 | B22: =B21+1 -> 36 | C22: =C21 -> 2217 | D22: =C22*L22 -> 34692.706 | F22: =E22*L22 -> 0 | G22: =F22+D22 -> 34692.706 | I22: 0 | J22: 35000 | K22: =J22*L22 -> 547697.2 | L22: =L21*1.045 -> 15.648492
A23: 15 | B23: =B22+1 -> 37 | C23: =C22 -> 2217 | D23: =C23*L23 -> 36253.877 | F23: =E23*L23 -> 0 | G23: =F23+D23 -> 36253.877 | H23: 1750 | I23: =H23*L23 -> 28617.179 | J23: 35000 | K23: =J23*L23 -> 572343.58 | L23: =L22*1.045 -> 16.352674
A24: 16 | B24: =B23+1 -> 38 | C24: =C23 -> 2217 | D24: =C24*L24 -> 37885.302 | F24: =E24*L24 -> 0 | G24: =F24+D24 -> 37885.302 | I24: 0 | J24: 35000 | K24: =J24*L24 -> 598099.04 | L24: =L23*1.045 -> 17.088544
A25: 17 | B25: =B24+1 -> 39 | C25: =C24 -> 2217 | D25: =C25*L25 -> 39590.141 | F25: =E25*L25 -> 0 | G25: =F25+D25 -> 39590.141 | H25: 1750 | I25: =H25*L25 -> 31250.675 | J25: 35000 | K25: =J25*L25 -> 625013.5 | L25: =L24*1.045 -> 17.857528
A26: 18 | B26: =B25+1 -> 40 | C26: =C25 -> 2217 | D26: =C26*L26 -> 41371.697 | F26: =E26*L26 -> 0 | G26: =F26+D26 -> 41371.697 | I26: 0 | J26: 35000 | K26: =J26*L26 -> 653139.1 | L26: =L25*1.045 -> 18.661117
A27: 19 | B27: =B26+1 -> 41 | C27: =C26 -> 2217 | D27: =C27*L27 -> 43233.423 | F27: =E27*L27 -> 0 | G27: =F27+D27 -> 43233.423 | I27: 0 | J27: 35000 | K27: =J27*L27 -> 682530.36 | L27: =L26*1.045 -> 19.500868
A28: 20 | B28: =B27+1 -> 42 | C28: =C27 -> 2217 | D28: =C28*L28 -> 45178.927 | F28: =E28*L28 -> 0 | G28: =F28+D28 -> 45178.927 | H28: 28000 | I28: =H28*L28 -> 570595.38 | J28: 35000 | K28: =J28*L28 -> 713244.23 | L28: =L27*1.045 -> 20.378407
F29: =SUM(F9:F28) -> 0 | G29: =SUM(G9:G28) -> 614130.42
C30: =SUM(D9:D29) -> 614130.42 | E30: Ahorro | I30: =I13+I15+I17+I19+I21+I23+I25+I28+F29 -> 682989.18 | L30: =G9/365 -> 53.633178 | M30: DIARIO
D32: =I30-G30 -> 682989.18 | J32: Recuperación

Sheet REALIZA
B2: MARISOL | C2: AHORRO ANUAL | E2: ADICIONAL | G2: FONDO C/ADIC | I2: FONDO S/ADIC | K2: PROTECCION | M2: UDI
C3: udi | D3: pesos | E3: udi | F3: pesos | G3: udi | H3: pesos | I3: udi | J3: pesos | K3: udi | L3: pesos
A4: 1 | B4: 34 | C4: 2274 | D4: =C4*M4 -> 13891.425 | E4: 6000 | F4: =E4*M4 -> 36652.836 | G4: 4948 | H4: =G4*M4 -> 30226.372 | I4: 0 | J4: 0 | K4: 200000 | L4: =K4*M4 -> 1221761.2 | M4: 6.108806
A5: 2 | B5: 35 | C5: 2274 | D5: =C5*M5 -> 14516.539 | E5: 6000 | F5: =E5*M5 -> 38302.214 | G5: 12982 | H5: =G5*M5 -> 82873.223 | I5: 551 | J5: 3517.42 | K5: 200000 | L5: =K5*M5 -> 1276740.5 | M5: 6.3837023
A6: 3 | B6: 36 | C6: 2274 | D6: =C6*M6 -> 15169.783 | E6: 6000 | F6: =E6*M6 -> 40025.813 | G6: 21247 | H6: =G6*M6 -> 141738.08 | I6: 2308 | J6: 15396.596 | K6: 200000 | L6: =K6*M6 -> 1334193.8 | M6: 6.6709689
A7: 4 | B7: 37 | C7: 2274 | D7: =C7*M7 -> 15852.423 | E7: 6000 | F7: =E7*M7 -> 41826.975 | G7: 29750 | H7: =G7*M7 -> 207392.08 | I7: 4097 | J7: 28560.853 | K7: 200000 | L7: =K7*M7 -> 1394232.5 | M7: 6.9711625
A8: 5 | B8: 38 | C8: 2274 | D8: =C8*M8 -> 16565.783 | E8: 6000 | F8: =E8*M8 -> 43709.189 | G8: 38500 | H8: =G8*M8 -> 280467.29 | I8: 5918 | J8: 43111.83 | K8: 200000 | L8: =K8*M8 -> 1456973 | M8: 7.2848648
A9: 6 | B9: 39 | C9: 2274 | D9: =C9*M9 -> 17311.243 | F9: =E9*M9 -> 0 | G9: 41384 | H9: =G9*M9 -> 315043.3 | I9: 7770 | J9: 59150.552 | K9: 200000 | L9: =K9*M9 -> 1522536.7 | M9: 7.6126837
A10: 7 | B10: 40 | C10: 2274 | D10: =C10*M10 -> 18090.249 | F10: =E10*M10 -> 0 | G10: 44343 | H10: =G10*M10 -> 352759.85 | I10: 9653 | J10: 76792.071 | K10: 200000 | L10: =K10*M10 -> 1591050.9 | M10: 7.9552545
A11: 8 | B11: 41 | C11: 2274 | D11: =C11*M11 -> 18904.31 | F11: =E11*M11 -> 0 | G11: 47381 | H11: =G11*M11 -> 393889.67 | I11: 11568 | J11: 96167.571 | K11: 200000 | L11: =K11*M11 -> 1662648.2 | M11: 8.3132409
A12: 9 | B12: 42 | C12: 2274 | D12: =C12*M12 -> 19755.004 | F12: =E12*M12 -> 0 | G12: 50498 | H12: =G12*M12 -> 438693.13 | I12: 13513 | J12: 117391.98 | K12: 200000 | L12: =K12*M12 -> 1737467.4 | M12: 8.6873368
A13: 10 | B13: 43 | C13: 2274 | D13: =C13*M13 -> 20643.979 | F13: =E13*M13 -> 0 | G13: 53695 | H13: =G13*M13 -> 487457.54 | I13: 15488 | J13: 140604.2 | K13: 200000 | L13: =K13*M13 -> 1815653.4 | M13: 9.0782669
A14: 11 | B14: 44 | C14: 2274 | D14: =C14*M14 -> 21572.958 | F14: =E14*M14 -> 0 | G14: 57228 | H14: =G14*M14 -> 542909.96 | I14: 17746 | J14: 168352.56 | K14: 200000 | L14: =K14*M14 -> 1897357.8 | M14: 9.4867889
A15: 12 | B15: 45 | C15: 2274 | D15: =C15*M15 -> 22543.741 | F15: =E15*M15 -> 0 | G15: 60381 | H15: =G15*M15 -> 598598.78 | I15: 19568 | J15: 193991.17 | K15: 200000 | L15: =K15*M15 -> 1982738.9 | M15: 9.9136944
A16: 13 | B16: 46 | C16: 2274 | D16: =C16*M16 -> 23558.209 | F16: =E16*M16 -> 0 | G16: 63598 | H16: =G16*M16 -> 658863.24 | I16: 21398 | J16: 221679.23 | K16: 200000 | L16: =K16*M16 -> 2071962.1 | M16: 10.359811
A17: 14 | B17: 47 | C17: 2274 | D17: =C17*M17 -> 24618.329 | F17: =E17*M17 -> 0 | G17: 66877 | H17: =G17*M17 -> 724010.55 | I17: 23229 | J17: 251477.2 | K17: 200000 | L17: =K17*M17 -> 2165200.4 | M17: 10.826002
A18: 15 | B18: 48 | C18: 2274 | D18: =C18*M18 -> 25726.154 | F18: =E18*M18 -> 0 | G18: 70213 | H18: =G18*M18 -> 794331.76 | I18: 25054 | J18: 283440.22 | K18: 200000 | L18: =K18*M18 -> 2262634.4 | M18: 11.313172
A19: 16 | B19: 49 | C19: 2274 | D19: =C19*M19 -> 26883.831 | F19: =E19*M19 -> 0 | G19: 73601 | H19: =G19*M19 -> 870130.53 | I19: 26867 | J19: 317628.79 | K19: 200000 | L19: =K19*M19 -> 2364453 | M19: 11.822265
A20: 17 | B20: 50 | C20: 2274 | D20: =C20*M20 -> 28093.603 | F20: =E20*M20 -> 0 | G20: 77036 | H20: =G20*M20 -> 951723.31 | I20: 28657 | J20: 354036.23 | K20: 200000 | L20: =K20*M20 -> 2470853.4 | M20: 12.354267
... A23: 20 | B23: 53 | C23: 2274 | D23: =C23*M23 -> 30678.917 | F23: =E23*M23 -> 0 | G23: 87521 | H23: =G23*M23 -> 1180760.5 | I23: 33772 | J23: 455623.74 | K23: 200000 | L23: =K23*M23 -> 2698233.7 | M23: 13.491168
C27: AHORRO ANUAL | E27: =D4 -> 13891.425
B30: TIEMPO | D30: AHORRO | F30: DISPONIBLE | H30: GANANCIA
B32: 10 AÑOS | D32: =SUM(D4:D13) -> 170700.74 | F32: =J13 -> 140604.2
B34: 15 AÑOS | D34: =SUM(D4:D18) -> 288720.13 | F34: =J18 -> 283440.22
B36: 20 AÑOS | D36: =SUM(D4:D23) -> 434413.21 | F36: =J23 -> 455623.74 | H36: =F36-D36 -> 21210.527
C39: AHORRO ANUAL | E39: =D4+F4 -> 50544.261
B42: TIEMPO | D42: AHORRO | F42: DISPONIBLE | H42: GANANCIA | K42: PP | L42: 0.6
K43: BU | L43: 0.2
B44: 10 AÑOS | D44: =SUM(D4:D13)+SUM(F4:F13) -> 371217.76 | F44: =H13 -> 487457.54 | H44: =F44-D44 -> 116239.78 | K44: CU | L44: 0.2
B46: 15 AÑOS | D46: =SUM(D4:D18)+SUM(F4:F18) -> 489237.15 | F46: =H18 -> 794331.76 | H46: =F46-D46 -> 305094.61
B48: 20 AÑOS | D48: =SUM(D4:D23)+SUM(F4:F8) -> 634930.24 | F48: =H23 -> 1180760.5 | H48: =F48-D48 -> 545830.31

Sheet IMAGINA
B3: Brian | C3: AHORRO ANUAL | E3: FONDO | G3: PROTECCION | I3: UDI | K3: JORGE | M3: AHORRO ANUAL | P3: UDI | R3: Pago Unico
C4: udi | D4: pesos | E4: udi | F4: pesos | G4: udi | H4: pesos | L4: Mensual | M4: anual | N4: pesos | O4: pesos
A5: 1 | B5: 23 | C5: 3222 | D5: =C5*I5 -> 28514.7 | E5: =Hoja5!I37 -> 0 | F5: =E5*I5 -> 0 | G5: 75000 | H5: =G5*I5 -> 663750 | I5: 8.85 | K5: 65 | L5: 606 | M5: =L5*12 -> 7272 | N5: =L5*P5 -> 34064.349 | O5: =M5*P5 -> 408772.19 | P5: =I5*(1.045^(K5-B5)) -> 56.211797 | Q5: 128697 | R5: =Q5*P5 -> 7234289.6
A6: 2 | B6: =B5+1 -> 24 | C6: =C5 -> 3222 | D6: =C6*I6 -> 29797.861 | E6: =Hoja5!I38 -> 0 | F6: =E6*I6 -> 0 | G6: =G5 -> 75000 | H6: =G6*I6 -> 693618.75 | I6: =I5*1.045 -> 9.24825 | K6: =K5+1 -> 66 | L6: 606 | M6: =L6*12 -> 7272 | N6: =L6*P6 -> 35597.245 | O6: =M6*P6 -> 427166.94 | P6: =P5*1.045 -> 58.741328 | Q6: 151512
A7: 3 | B7: =B6+1 -> 25 | C7: =C6 -> 3222 | D7: =C7*I7 -> 31138.765 | E7: =Hoja5!I39 -> 13467 | F7: =E7*I7 -> 130150.76 | G7: =G6 -> 75000 | H7: =G7*I7 -> 724831.59 | I7: =I6*1.045 -> 9.6644212 | K7: =K6+1 -> 67 | L7: =L6 -> 606 | M7: =L7*12 -> 7272 | N7: =L7*P7 -> 37199.121 | O7: =M7*P7 -> 446389.45 | P7: =P6*1.045 -> 61.384688
A8: 4 | B8: =B7+1 -> 26 | C8: =C7 -> 3222 | D8: =C8*I8 -> 32540.01 | E8: =Hoja5!I40 -> 21021 | F8: =E8*I8 -> 212297.81 | G8: =G7 -> 75000 | H8: =G8*I8 -> 757449.02 | I8: =I7*1.045 -> 10.09932 | K8: =K7+1 -> 68 | L8: =L7 -> 606 | M8: =L8*12 -> 7272 | N8: =L8*P8 -> 38873.081 | O8: =M8*P8 -> 466476.97 | P8: =P7*1.045 -> 64.146999
A9: 5 | B9: =B8+1 -> 27 | C9: =C8 -> 3222 | D9: =C9*I9 -> 34004.31 | E9: =Hoja5!I41 -> 29139 | F9: =E9*I9 -> 307526.88 | G9: =G8 -> 75000 | H9: =G9*I9 -> 791534.22 | I9: =I8*1.045 -> 10.55379 | K9: =K8+1 -> 69 | L9: =L8 -> 606 | M9: =L9*12 -> 7272 | N9: =L9*P9 -> 40622.37 | O9: =M9*P9 -> 487468.44 | P9: =P8*1.045 -> 67.033614
A10: 6 | B10: =B9+1 -> 28 | C10: =C9 -> 3222 | D10: =C10*I10 -> 35534.504 | E10: =Hoja5!I42 -> 37842 | F10: =E10*I10 -> 417348.45 | G10: =G9 -> 75000 | H10: =G10*I10 -> 827153.26 | I10: =I9*1.045 -> 11.02871 | K10: =K9+1 -> 70 | L10: =L9 -> 606 | M10: =L10*12 -> 7272 | N10: =L10*P10 -> 42450.376 | O10: =M10*P10 -> 509404.52 | P10: =P9*1.045 -> 70.050126
A11: 7 | B11: =B10+1 -> 29 | C11: =C10 -> 3222 | D11: =C11*I11 -> 37133.557 | E11: =Hoja5!I43 -> 47157 | F11: =E11*I11 -> 543484.52 | G11: =G10 -> 75000 | H11: =G11*I11 -> 864375.16 | I11: =I10*1.045 -> 11.525002 | K11: =K10+1 -> 71 | L11: =L10 -> 606 | M11: =L11*12 -> 7272 | N11: =L11*P11 -> 44360.643 | O11: =M11*P11 -> 532327.72 | P11: =P10*1.045 -> 73.202382
A12: 8 | B12: =B11+1 -> 30 | C12: =C11 -> 3222 | D12: =C12*I12 -> 38804.567 | E12: =Hoja5!I44 -> 57108 | F12: =E12*I12 -> 687787.46 | G12: =G11 -> 75000 | H12: =G12*I12 -> 903272.04 | I12: =I11*1.045 -> 12.043627 | K12: =K11+1 -> 72 | L12: =L11 -> 606 | M12: =L12*12 -> 7272 | N12: =L12*P12 -> 46356.872 | O12: =M12*P12 -> 556282.47 | P12: =P11*1.045 -> 76.496489
A13: 9 | B13: =B12+1 -> 31 | C13: =C12 -> 3222 | D13: =C13*I13 -> 40550.772 | E13: =Hoja5!I45 -> 67719 | F13: =E13*I13 -> 852283.6 | G13: =G12 -> 75000 | H13: =G13*I13 -> 943919.28 | I13: =I12*1.045 -> 12.58559 | K13: =K12+1 -> 73 | L13: =L12 -> 606 | M13: =L13*12 -> 7272 | N13: =L13*P13 -> 48442.932 | O13: =M13*P13 -> 581315.18 | P13: =P12*1.045 -> 79.938831
A14: 10 | B14: =B13+1 -> 32 | C14: =C13 -> 3222 | D14: =C14*I14 -> 42375.557 | E14: =Hoja5!I46 -> 79026 | F14: =E14*I14 -> 1039345.4 | G14: =G13 -> 75000 | H14: =G14*I14 -> 986395.65 | I14: =I13*1.045 -> 13.151942 | K14: =K13+1 -> 74 | L14: =L13 -> 606 | M14: =L14*12 -> 7272 | N14: =L14*P14 -> 50622.864 | O14: =M14*P14 -> 607474.36 | P14: =P13*1.045 -> 83.536078
A15: 11 | B15: =B14+1 -> 33 | C15: =C14 -> 3222 | D15: =C15*I15 -> 44282.457 | E15: =Hoja5!I47 -> 80862 | F15: =E15*I15 -> 1111349.5 | G15: =G14 -> 75000 | H15: =G15*I15 -> 1030783.5 | I15: =I14*1.045 -> 13.743779 | K15: =K14+1 -> 75 | L15: =L14 -> 606 | M15: =L15*12 -> 7272 | N15: =L15*P15 -> 52900.892 | O15: =M15*P15 -> 634810.71 | P15: =P14*1.045 -> 87.295202 | Q15: =SUM(M5:M15) -> 79992 | R15: =SUM(O5:O15) -> 5657888.9
A16: 12 | B16: =B15+1 -> 34 | C16: =C15 -> 3222 | D16: =C16*I16 -> 46275.168 | E16: =Hoja5!I48 -> 98073 | F16: =E16*I16 -> 1408548.9 | G16: =G15 -> 75000 | H16: =G16*I16 -> 1077168.7 | I16: =I15*1.045 -> 14.362249 | K16: =K15+1 -> 76 | L16: =L15 -> 606 | M16: =L16*12 -> 7272 | N16: =L16*P16 -> 55281.433 | O16: =M16*P16 -> 663377.19 | P16: =P15*1.045 -> 91.223486
A17: 13 | B17: =B16+1 -> 35 | C17: =C16 -> 3222 | D17: =C17*I17 -> 48357.55 | E17: =Hoja5!I49 -> 115815 | F17: =E17*I17 -> 1738215.3 | G17: =G16 -> 75000 | H17: =G17*I17 -> 1125641.3 | I17: =I16*1.045 -> 15.008551 | K17: =K16+1 -> 77 | L17: =L16 -> 606 | M17: =L17*12 -> 7272 | N17: =L17*P17 -> 57769.097 | O17: =M17*P17 -> 693229.16 | P17: =P16*1.045 -> 95.328543
A18: 14 | B18: =B17+1 -> 36 | C18: =C17 -> 3222 | D18: =C18*I18 -> 50533.64 | E18: =Hoja5!I50 -> 134118 | F18: =E18*I18 -> 2103498.1 | G18: =G17 -> 75000 | H18: =G18*I18 -> 1176295.2 | I18: =I17*1.045 -> 15.683935 | K18: =K17+1 -> 78 | L18: =L17 -> 606 | M18: =L18*12 -> 7272 | N18: =L18*P18 -> 60368.706 | O18: =M18*P18 -> 724424.48 | P18: =P17*1.045 -> 99.618327
A19: 15 | B19: =B18+1 -> 37 | C19: =C18 -> 3222 | D19: =C19*I19 -> 52807.654 | E19: =Hoja5!I51 -> 154044 | F19: =E19*I19 -> 2524736.9 | G19: =G18 -> 75000 | H19: =G19*I19 -> 1229228.4 | I19: =I18*1.045 -> 16.389713 | K19: =K18+1 -> 79 | L19: =L18 -> 606 | M19: =L19*12 -> 7272 | N19: =L19*P19 -> 63085.298 | O19: =M19*P19 -> 757023.58 | P19: =P18*1.045 -> 104.10115
A20: 16 | B20: =B19+1 -> 38 | D20: =C20*I20 -> 0 | E20: =Hoja5!I52 -> 160647 | F20: =E20*I20 -> 2751441.3 | G20: =G19 -> 75000 | H20: =G20*I20 -> 1284543.7 | I20: =I19*1.045 -> 17.12725 | K20: =K19+1 -> 80 | L20: =L19 -> 606 | M20: =L20*12 -> 7272 | N20: =L20*P20 -> 65924.137 | O20: =M20*P20 -> 791089.64 | P20: =P19*1.045 -> 108.7857 | Q20: =SUM(M5:M20) -> 116352 | R20: =SUM(O5:O20) -> 9287033
A21: 17 | B21: =B20+1 -> 39 | D21: =C21*I21 -> 0 | E21: =Hoja5!I53 -> 167433 | F21: =E21*I21 -> 2996711.8 | G21: =G20 -> 75000 | H21: =G21*I21 -> 1342348.2 | I21: =I20*1.045 -> 17.897976 | K21: =K20+1 -> 81 | L21: =L20 -> 606 | M21: =L21*12 -> 7272 | N21: =L21*P21 -> 68890.723 | O21: =M21*P21 -> 826688.67 | P21: =P20*1.045 -> 113.68106
A22: 18 | B22: =B21+1 -> 40 | D22: =C22*I22 -> 0 | E22: =Hoja5!I54 -> 174405 | F22: =E22*I22 -> 3261963.8 | G22: =G21 -> 75000 | H22: =G22*I22 -> 1402753.9 | I22: =I21*1.045 -> 18.703385 | K22: =K21+1 -> 82 | L22: =L21 -> 606 | M22: =L22*12 -> 7272 | N22: =L22*P22 -> 71990.805 | O22: =M22*P22 -> 863889.66 | P22: =P21*1.045 -> 118.79671
A23: 19 | B23: =B22+1 -> 41 | D23: =C23*I23 -> 0 | E23: =Hoja5!I55 -> 181572 | F23: =E23*I23 -> 3548831.5 | G23: =G22 -> 75000 | H23: =G23*I23 -> 1465877.8 | I23: =I22*1.045 -> 19.545037 | K23: =K22+1 -> 83 | L23: =L22 -> 606 | M23: =L23*12 -> 7272 | N23: =L23*P23 -> 75230.391 | O23: =M23*P23 -> 902764.7 | P23: =P22*1.045 -> 124.14256
A24: 20 | B24: =B23+1 -> 42 | D24: =C24*I24 -> 0 | E24: =Hoja5!I56 -> 188949 | F24: =E24*I24 -> 3859200.9 | G24: =G23 -> 75000 | H24: =G24*I24 -> 1531842.3 | I24: =I23*1.045 -> 20.424564 | K24: =K23+1 -> 84 | L24: =L23 -> 606 | M24: =L24*12 -> 7272 | N24: =L24*P24 -> 78615.759 | O24: =M24*P24 -> 943389.11 | P24: =P23*1.045 -> 129.72898
A25: 21 | B25: =B24+1 -> 43 | D25: =C25*I25 -> 0 | E25: =Hoja5!I57 -> 196542 | F25: =E25*I25 -> 4194927.4 | G25: =G24 -> 75000 | H25: =G25*I25 -> 1600775.2 | I25: =I24*1.045 -> 21.343669 | K25: =K24+1 -> 85 | L25: =L24 -> 606 | M25: =L25*12 -> 7272 | N25: =L25*P25 -> 82153.468 | O25: =M25*P25 -> 985841.62 | P25: =P24*1.045 -> 135.56678 | R25: =SUM(O5:O25) -> 13809607
A26: 22 | B26: =B25+1 -> 44 | D26: =C26*I26 -> 0 | E26: =Hoja5!I58 -> 204366 | F26: =E26*I26 -> 4558206.7 | G26: =G25 -> 75000 | H26: =G26*I26 -> 1672810.1 | I26: =I25*1.045 -> 22.304134 | K26: =K25+1 -> 86 | L26: =L25 -> 606 | M26: =L26*12 -> 7272 | N26: =L26*P26 -> 85850.374 | O26: =M26*P26 -> 1030204.5 | P26: =P25*1.045 -> 141.66728
A27: 23 | B27: =B26+1 -> 45 | D27: =C27*I27 -> 0 | E27: =Hoja5!I59 -> 212442 | F27: =E27*I27 -> 4951560 | G27: =G26 -> 75000 | H27: =G27*I27 -> 1748086.5 | I27: =I26*1.045 -> 23.30782 | K27: =K26+1 -> 87 | L27: =L26 -> 606 | M27: =L27*12 -> 7272 | N27: =L27*P27 -> 89713.641 | O27: =M27*P27 -> 1076563.7 | P27: =P26*1.045 -> 148.04231
A28: 24 | B28: =B27+1 -> 46 | D28: =C28*I28 -> 0 | E28: =Hoja5!I60 -> 220779 | F28: =E28*I28 -> 5377441.7 | G28: =G27 -> 75000 | H28: =G28*I28 -> 1826750.4 | I28: =I27*1.045 -> 24.356672 | K28: =K27+1 -> 88 | L28: =L27 -> 606 | M28: =L28*12 -> 7272 | N28: =L28*P28 -> 93750.755 | O28: =M28*P28 -> 1125009.1 | P28: =P27*1.045 -> 154.70422
A29: 25 | B29: =B28+1 -> 47 | D29: =C29*I29 -> 0 | E29: =Hoja5!I61 -> 229398 | F29: =E29*I29 -> 5838803.6 | G29: =G28 -> 75000 | H29: =G29*I29 -> 1908954.2 | I29: =I28*1.045 -> 25.452722 | K29: =K28+1 -> 89 | L29: =L28 -> 606 | M29: =L29*12 -> 7272 | N29: =L29*P29 -> 97969.539 | O29: =M29*P29 -> 1175634.5 | P29: =P28*1.045 -> 161.66591
A30: 26 | B30: =B29+1 -> 48 | D30: =C30*I30 -> 0 | E30: =Hoja5!I62 -> 238326 | F30: =E30*I30 -> 6339017.6 | G30: =G29 -> 75000 | H30: =G30*I30 -> 1994857.1 | I30: =I29*1.045 -> 26.598095 | K30: =K29+1 -> 90 | L30: =L29 -> 606 | M30: =L30*12 -> 7272 | N30: =L30*P30 -> 102378.17 | O30: =M30*P30 -> 1228538 | P30: =P29*1.045 -> 168.94087 | R30: =SUM(O5:O30) -> 19445556
A31: 27 | B31: =B30+1 -> 49 | D31: 0 | F31: 0 | H31: 0 | I31: =I30*1.045 -> 27.795009 | K31: =K30+1 -> 91 | L31: =L30 -> 606 | M31: =L31*12 -> 7272 | N31: =L31*P31 -> 106985.19 | O31: =M31*P31 -> 1283822.2 | P31: =P30*1.045 -> 176.54321
A32: 28 | B32: =B31+1 -> 50 | D32: 0 | F32: 0 | H32: 0 | I32: =I31*1.045 -> 29.045785 | K32: =K31+1 -> 92 | L32: =L31 -> 606 | M32: =L32*12 -> 7272 | N32: =L32*P32 -> 111799.52 | O32: =M32*P32 -> 1341594.2 | P32: =P31*1.045 -> 184.48766
A33: 29 | B33: =B32+1 -> 51 | D33: 0 | F33: 0 | H33: 0 | I33: =I32*1.045 -> 30.352845 | K33: =K32+1 -> 93 | L33: =L32 -> 606 | M33: =L33*12 -> 7272 | N33: =L33*P33 -> 116830.5 | O33: =M33*P33 -> 1401966 | P33: =P32*1.045 -> 192.7896
A34: 30 | B34: =B33+1 -> 52 | D34: 0 | F34: 0 | H34: 0 | I34: =I33*1.045 -> 31.718723 | K34: =K33+1 -> 94 | L34: =L33 -> 606 | M34: =L34*12 -> 7272 | N34: =L34*P34 -> 122087.87 | O34: =M34*P34 -> 1465054.4 | P34: =P33*1.045 -> 201.46513
A35: 31 | B35: =B34+1 -> 53 | D35: 0 | F35: 0 | H35: 0 | I35: =I34*1.045 -> 33.146065 | K35: =K34+1 -> 95 | L35: =L34 -> 606 | M35: =L35*12 -> 7272 | N35: =L35*P35 -> 127581.82 | O35: =M35*P35 -> 1530981.9 | P35: =P34*1.045 -> 210.53106
A36: 32 | B36: =B35+1 -> 54 | D36: 0 | F36: 0 | H36: 0 | I36: =I35*1.045 -> 34.637638 | K36: =K35+1 -> 96 | L36: =L35 -> 606 | M36: =L36*12 -> 7272 | N36: =L36*P36 -> 133323.01 | O36: =M36*P36 -> 1599876.1 | P36: =P35*1.045 -> 220.00496
A37: 33 | B37: =B36+1 -> 55 | D37: 0 | F37: 0 | H37: 0 | I37: =I36*1.045 -> 36.196332 | K37: =K36+1 -> 97 | L37: =L36 -> 606 | M37: =L37*12 -> 7272 | N37: =L37*P37 -> 139322.54 | O37: =M37*P37 -> 1671870.5 | P37: =P36*1.045 -> 229.90518
A38: 34 | B38: =B37+1 -> 56 | D38: 0 | F38: 0 | H38: 0 | I38: =I37*1.045 -> 37.825167 | K38: =K37+1 -> 98 | L38: =L37 -> 606 | M38: =L38*12 -> 7272 | N38: =L38*P38 -> 145592.06 | O38: =M38*P38 -> 1747104.7 | P38: =P37*1.045 -> 240.25092
A39: 35 | B39: =B38+1 -> 57 | D39: 0 | F39: 0 | H39: 0 | I39: =I38*1.045 -> 39.5273 | K39: =K38+1 -> 99 | L39: =L38 -> 606 | M39: =L39*12 -> 7272 | N39: =L39*P39 -> 152143.7 | O39: =M39*P39 -> 1825724.4 | P39: =P38*1.045 -> 251.06221
A40: 36 | B40: =B39+1 -> 58 | D40: 0 | F40: 0 | H40: 0 | I40: =I39*1.045 -> 41.306028 | K40: =K39+1 -> 100 | L40: =L39 -> 606 | M40: =L40*12 -> 7272 | N40: =L40*P40 -> 158990.16 | O40: =M40*P40 -> 1907882 | P40: =P39*1.045 -> 262.36001
A41: 37 | B41: =B40+1 -> 59 | D41: 0 | F41: 0 | H41: 0 | I41: =I40*1.045 -> 43.164799 | K41: =K40+1 -> 101 | L41: =L40 -> 606 | M41: =L41*12 -> 7272 | N41: =L41*P41 -> 166144.72 | O41: =M41*P41 -> 1993736.7 | P41: =P40*1.045 -> 274.16621
A42: 38 | B42: =B41+1 -> 60 | D42: 0 | F42: 0 | H42: 0 | I42: =I41*1.045 -> 45.107215 | K42: =K41+1 -> 102 | L42: =L41 -> 606 | M42: =L42*12 -> 7272 | N42: =L42*P42 -> 173621.23 | O42: =M42*P42 -> 2083454.8 | P42: =P41*1.045 -> 286.50369
...

Sheet Hoja2

Sheet ORVI
B2: ANTONIO | C2: AHORRO ANUAL | E2: FONDO | G2: PROTECCION | I2: UDI | J2: DISPONIBLE | K2: PESOS
C3: udi | D3: pesos | E3: udi | F3: pesos | G3: udi | H3: pesos
A4: 1 | B4: 31 | C4: 9575 | D4: =C4*I4 -> 80717.25 | E4: 90000 | F4: - | G4: 60000 | H4: =G4*I4 -> 505800 | I4: 8.43 | J4: 1179 | M4: =J4*I4 -> 9938.97 | O4: =N4*I4 -> 0
A5: 2 | B5: =B4+1 -> 32 | C5: =C4 -> 9575 | D5: =C5*I5 -> 84349.526 | E5: =E4 -> 90000 | F5: - | G5: =G4 -> 60000 | H5: =G5*I5 -> 528561 | I5: =I4*1.045 -> 8.80935 | J5: 2377 | M5: =J5*I5 -> 20939.825 | O5: =N5*I5 -> 0
A6: 3 | B6: =B5+1 -> 33 | C6: =C5 -> 9575 | D6: =C6*I6 -> 88145.255 | E6: 3333 | F6: =E6*I6 -> 30682.834 | G6: =G5 -> 60000 | H6: =G6*I6 -> 552346.24 | I6: =I5*1.045 -> 9.2057707 | J6: 3594 | M6: =J6*I6 -> 33085.54 | O6: =I6*N6 -> 0
A7: 4 | B7: =B6+1 -> 34 | C7: =C6 -> 9575 | D7: =C7*I7 -> 92111.791 | E7: 5299 | F7: =E7*I7 -> 50976.541 | G7: =G6 -> 60000 | H7: =G7*I7 -> 577201.83 | I7: =I6*1.045 -> 9.6200304 | J7: 22524 | M7: =J7*I7 -> 216681.57 | O7: =N6*I7 -> 0
A8: 5 | B8: =B7+1 -> 35 | C8: =C7 -> 9575 | D8: =C8*I8 -> 96256.822 | E8: 7381 | F8: =E8*I8 -> 74200.69 | G8: =G7 -> 60000 | H8: =G8*I8 -> 603175.91 | I8: =I7*1.045 -> 10.052932 | J8: 26978 | K8: =J8*I8 -> 271207.99 | M8: =J8*I8 -> 271207.99 | O8: =N7*I8 -> 0
A9: 6 | B9: =B8+1 -> 36 | C9: =C8 -> 9575 | D9: =C9*I9 -> 100588.38 | E9: 7382 | F9: =E9*I9 -> 77550.226 | G9: =G8 -> 60000 | H9: =G9*I9 -> 630318.82 | I9: =I8*1.045 -> 10.505314 | J9: 7359 | M9: =J9*I9 -> 77308.604 | O9: =N8*I9 -> 0
A10: 7 | B10: =B9+1 -> 37 | C10: =C9 -> 9575 | D10: =C10*I10 -> 105114.86 | E10: 7383 | F10: =E10*I10 -> 81050.964 | G10: =G9 -> 60000 | H10: =G10*I10 -> 658683.17 | I10: =I9*1.045 -> 10.978053 | J10: 8654 | M10: =J10*I10 -> 95004.069 | O10: =N9*I10 -> 0
A11: 8 | B11: =B10+1 -> 38 | C11: =C10 -> 9575 | D11: =C11*I11 -> 109845.02 | E11: 7384 | F11: =E11*I11 -> 84709.73 | G11: =G10 -> 60000 | H11: =G11*I11 -> 688323.91 | I11: =I10*1.045 -> 11.472065 | J11: 9969 | M11: =J11*I11 -> 114365.02 | O11: =N10*I11 -> 0
A12: 9 | B12: =B11+1 -> 39 | C12: =C11 -> 9575 | D12: =C12*I12 -> 114788.05 | E12: 7385 | F12: =E12*I12 -> 88533.656 | G12: =G11 -> 60000 | H12: =G12*I12 -> 719298.49 | I12: =I11*1.045 -> 11.988308 | J12: 11305 | M12: =J12*I12 -> 135527.82 | O12: =N11*I12 -> 0
A13: 10 | B13: =B12+1 -> 40 | C13: =C12 -> 9575 | D13: =C13*I13 -> 119953.51 | E13: 7386 | F13: =E13*I13 -> 92530.198 | G13: =G12 -> 60000 | H13: =G13*I13 -> 751666.92 | I13: =I12*1.045 -> 12.527782 | J13: 70098 | K13: =J12*I13 -> 141626.58 | L13: 65000 | M13: =J13*I13 -> 878172.46 | O13: =N12*I13 -> 0
A14: 11 | B14: =B13+1 -> 41 | C14: =C13 -> 9575 | D14: =C14*I14 -> 125351.42 | E14: 18108 | F14: =E14*I14 -> 237061.47 | G14: =G13 -> 60000 | H14: =G14*I14 -> 785491.93 | I14: =I13*1.045 -> 13.091532 | O14: =N13*I14 -> 0
A15: 12 | B15: =B14+1 -> 42 | C15: =C14 -> 9575 | D15: =C15*I15 -> 130992.24 | E15: 18109 | F15: =E15*I15 -> 247742.91 | G15: =G14 -> 60000 | H15: =G15*I15 -> 820839.07 | I15: =I14*1.045 -> 13.680651
A16: 13 | B16: =B15+1 -> 43 | C16: =C15 -> 9575 | D16: =C16*I16 -> 136886.89 | E16: 18110 | F16: =E16*I16 -> 258905.64 | G16: =G15 -> 60000 | H16: =G16*I16 -> 857776.83 | I16: =I15*1.045 -> 14.29628
A17: 14 | B17: =B16+1 -> 44 | C17: =C16 -> 9575 | D17: =C17*I17 -> 143046.8 | E17: 18111 | F17: =E17*I17 -> 270571.33 | G17: =G16 -> 60000 | H17: =G17*I17 -> 896376.79 | I17: =I16*1.045 -> 14.939613
A18: 15 | B18: =B17+1 -> 45 | C18: =C17 -> 9575 | D18: =C18*I18 -> 149483.9 | E18: 18112 | F18: =E18*I18 -> 282762.65 | G18: =G17 -> 60000 | H18: =G18*I18 -> 936713.74 | I18: =I17*1.045 -> 15.611896 | J18: 78005 | K18: =J18*I18 -> 1217805.9 | M18: =J18*I18 -> 1217805.9
A19: 16 | B19: =B18+1 -> 46 | C19: =C18 -> 9575 | D19: =C19*I19 -> 156210.68 | E19: 18113 | F19: =E19*I19 -> 295503.29 | G19: =G18 -> 60000 | H19: =G19*I19 -> 978865.86 | I19: =I18*1.045 -> 16.314431
A20: 17 | B20: =B19+1 -> 47 | C20: =C19 -> 9575 | D20: =C20*I20 -> 163240.16 | E20: 18114 | F20: =E20*I20 -> 308817.99 | G20: =G19 -> 60000 | H20: =G20*I20 -> 1022914.8 | I20: =I19*1.045 -> 17.04858 | J20: 56681 | M20: =J20*I20 -> 966330.59
A21: 18 | B21: =B20+1 -> 48 | C21: =C20 -> 9575 | D21: =C21*I21 -> 170585.96 | E21: 18115 | F21: =E21*I21 -> 322732.61 | G21: =G20 -> 60000 | H21: =G21*I21 -> 1068946 | I21: =I20*1.045 -> 17.815767
A22: 19 | B22: =B21+1 -> 49 | C22: =C21 -> 9575 | D22: =C22*I22 -> 178262.33 | E22: 18116 | F22: =E22*I22 -> 337274.2 | G22: =G21 -> 60000 | H22: =G22*I22 -> 1117048.6 | I22: =I21*1.045 -> 18.617476
A23: 20 | B23: =B22+1 -> 50 | C23: =C22 -> 9575 | D23: =C23*I23 -> 186284.14 | E23: 18116 | F23: =E23*I23 -> 352451.53 | G23: =G22 -> 60000 | H23: =G23*I23 -> 1167315.7 | I23: =I22*1.045 -> 19.455262 | J23: 36193 | K23: =J23*I23 -> 704144.31 | M23: =J23*I23 -> 704144.31 | O23: 120000 | P23: =O23*I23 -> 2334631.5
A24: 21 | B24: =B23+1 -> 51 | E24: 18117 | F24: =E24*I24 -> 368332.18 | G24: =G23 -> 60000 | H24: =G24*I24 -> 1219845 | I24: =I23*1.045 -> 20.330749
A25: 22 | B25: =B24+1 -> 52 | E25: 18118 | F25: =E25*I25 -> 384928.38 | G25: =G24 -> 60000 | H25: =G25*I25 -> 1274738 | I25: =I24*1.045 -> 21.245633 | J25: 61629 | M25: =J25*I25 -> 1309347.1
A26: 23 | B26: =B25+1 -> 53 | E26: 18119 | F26: =E26*I26 -> 402272.36 | G26: =G25 -> 60000 | H26: =G26*I26 -> 1332101.2 | I26: =I25*1.045 -> 22.201686 | M26: =J26*I26 -> 0
A27: 24 | B27: =B26+1 -> 54 | E27: 18120 | F27: =E27*I27 -> 420397.81 | G27: =G26 -> 60000 | H27: =G27*I27 -> 1392045.7 | I27: =I26*1.045 -> 23.200762
A28: 25 | B28: =B27+1 -> 55 | E28: 18121 | F28: =E28*I28 -> 439339.96 | G28: =G27 -> 60000 | H28: =G28*I28 -> 1454687.8 | I28: =I27*1.045 -> 24.244797 | J28: 40883 | K28: =J28*I28 -> 991200.02 | M28: =J28*I28 -> 991200.02
A29: 26 | B29: =B28+1 -> 56 | E29: 18122 | F29: =E29*I29 -> 459135.59 | G29: =G28 -> 60000 | H29: =G29*I29 -> 1520148.7 | I29: =I28*1.045 -> 25.335812
A30: 27 | B30: =B29+1 -> 57 | E30: 18123 | F30: =E30*I30 -> 479823.17 | G30: =G29 -> 60000 | H30: =G30*I30 -> 1588555.4 | I30: =I29*1.045 -> 26.475924 | J30: 69077 | M30: =J30*I30 -> 1828877.4
A31: 28 | B31: =B30+1 -> 58 | E31: 18124 | F31: =E31*I31 -> 501442.88 | G31: =G30 -> 60000 | H31: =G31*I31 -> 1660040.4 | I31: =I30*1.045 -> 27.667341 | J31: 30067 | M31: =J31*I31 -> 831873.93
A32: 29 | B32: =B31+1 -> 59 | E32: 18125 | F32: =E32*I32 -> 524036.72 | G32: =G31 -> 60000 | H32: =G32*I32 -> 1734742.3 | I32: =I31*1.045 -> 28.912371
A33: 30 | B33: =B32+1 -> 60 | E33: 18126 | F33: =E33*I33 -> 547648.59 | G33: =G32 -> 60000 | H33: =G33*I33 -> 1812805.7 | I33: =I32*1.045 -> 30.213428 | J33: 45807 | K33: =J33*I33 -> 1383986.5 | M33: =J33*I33 -> 1383986.5
A34: 31 | B34: =B33+1 -> 61 | E34: 18127 | F34: =E34*I34 -> 572324.35 | G34: =G33 -> 60000 | H34: =G34*I34 -> 1894381.9 | I34: =I33*1.045 -> 31.573032
A35: 32 | B35: =B34+1 -> 62 | E35: 18128 | F35: =E35*I35 -> 598111.94 | G35: =G34 -> 60000 | H35: =G35*I35 -> 1979629.1 | I35: =I34*1.045 -> 32.993818 | J35: 94246 | M35: =J35*I35 -> 3109535.4
A36: 33 | B36: =B35+1 -> 63 | E36: 18129 | F36: =E36*I36 -> 625061.45 | G36: =G35 -> 60000 | H36: =G36*I36 -> 2068712.4 | I36: =I35*1.045 -> 34.47854 | J36: 62128 | M36: =J36*I36 -> 2142082.7
A37: 34 | B37: =B36+1 -> 64 | E37: 18130 | F37: =E37*I37 -> 653225.25 | G37: =G36 -> 60000 | H37: =G37*I37 -> 2161804.5 | I37: =I36*1.045 -> 36.030074 | J37: 182124 | M37: =J37*I37 -> 6561941.3
A38: 35 | B38: =B37+1 -> 65 | E38: 18131 | F38: =E38*I38 -> 682658.04 | G38: =G37 -> 60000 | H38: =G38*I38 -> 2259085.7 | I38: =I37*1.045 -> 37.651428 | J38: 49073 | M38: =J38*I38 -> 1847668.5
A39: 36 | B39: =B38+1 -> 66 | E39: 18132 | F39: =E39*I39 -> 713416.99 | G39: =G38 -> 60000 | H39: =G39*I39 -> 2360744.5 | I39: =I38*1.045 -> 39.345742 | J39: 47028 | M39: =J39*I39 -> 1850351.6
A40: 37 | B40: =B39+1 -> 67 | E40: 18133 | F40: =E40*I40 -> 745561.88 | G40: =G39 -> 60000 | H40: =G40*I40 -> 2466978 | I40: =I39*1.045 -> 41.1163 | J40: 66724 | M40: =J40*I40 -> 2743444
A41: 38 | B41: =B40+1 -> 68 | E41: 18134 | F41: =E41*I41 -> 779155.13 | G41: =G40 -> 60000 | H41: =G41*I41 -> 2577992 | I41: =I40*1.045 -> 42.966534
...

Sheet Hoja5
D3: 29 | E3: 2968 | F3: 0 | G3: 0 | H3: % | I3: 85000 | J3: 0 | K3: 0
D4: 30 | E4: 2968 | F4: 0 | G4: 0 | H4: % | I4: 85000 | J4: 0 | K4: 0
D5: 31 | E5: 2968 | F5: 3333 | G5: 37.43 | H5: % | I5: 85000 | J5: 0 | K5: 0
D6: 32 | E6: 2968 | F6: 5299 | G6: 44.63 | H6: % | I6: 85000 | J6: 0 | K6: 0
D7: 33 | E7: 2968 | F7: 7381 | G7: 49.73 | H7: % | I7: 85000 | J7: 0 | K7: 0
D8: 34 | E8: 2968 | F8: 10006 | G8: 56.19 | H8: % | I8: 85000 | J8: 0 | K8: 0
D9: 35 | E9: 2968 | F9: 12515 | G9: 60.24 | H9: % | I9: 85000 | J9: 0 | K9: 0
D10: 36 | E10: 2968 | F10: 15213 | G10: 64.07 | H10: % | I10: 85000 | J10: 0 | K10: 0
D11: 37 | E11: 2968 | F11: 18107 | G11: 67.78 | H11: % | I11: 85000 | J11: 0 | K11: 0
D12: 38 | E12: 2968 | F12: 22892 | G12: 77.13 | H12: % | I12: 85000 | J12: 0 | K12: 0
D13: 39 | E13: 0 | F13: 23548 | G13: 79.34 | H13: % | I13: 85000 | J13: 0 | K13: 0
D14: 40 | E14: 0 | F14: 24218 | G14: 81.6 | H14: % | I14: 85000 | J14: 0 | K14: 0
... D34: 60 | E34: 0 | F34: 42282 | G34: 142.46 | H34: % | I34: 85000 | J34: 0 | K34: 0
C37: 1 | D37: 2020 | E37: 33 | F37: 300000 | G37: 13232 | H37: 13232 | I37: 0 | J37: 0 | K37: %
C38: 2 | D38: 2021 | E38: 34 | F38: 300000 | G38: 13232 | H38: 26465 | I38: 0 | J38: 0 | K38: %
C39: 3 | D39: 2022 | E39: 35 | F39: 300000 | G39: 13232 | H39: 39697 | I39: 13467 | J39: 34 | K39: %
C40: 4 | D40: 2023 | E40: 36 | F40: 300000 | G40: 13232 | H40: 52930 | I40: 21021 | J40: 40 | K40: %
C41: 5 | D41: 2024 | E41: 37 | F41: 300000 | G41: 13232 | H41: 66162 | I41: 29139 | J41: 44 | K41: %
C42: 6 | D42: 2025 | E42: 38 | F42: 300000 | G42: 13232 | H42: 79395 | I42: 37842 | J42: 48 | K42: %
C43: 7 | D43: 2026 | E43: 39 | F43: 300000 | G43: 13232 | H43: 92627 | I43: 47157 | J43: 51 | K43: %
C44: 8 | D44: 2027 | E44: 40 | F44: 300000 | G44: 13232 | H44: 105860 | I44: 57108 | J44: 54 | K44: %
C45: 9 | D45: 2028 | E45: 41 | F45: 300000 | G45: 13232 | H45: 119092 | I45: 67719 | J45: 57 | K45: %
C46: 10 | D46: 2029 | E46: 42 | F46: 300000 | G46: 13232 | H46: 132325 | I46: 79026 | J46: 60 | K46: %
C47: 11 | D47: 2030 | E47: 43 | F47: 300000 | G47: 11672 | H47: 143997 | I47: 80862 | J47: 56 | K47: %
C48: 12 | D48: 2031 | E48: 44 | F48: 300000 | G48: 11672 | H48: 155670 | I48: 98073 | J48: 63 | K48: %
... C68: 32 | D68: 2051 | E68: 64 | F68: 300000 | G68: 0 | H68: 190687 | I68: 300000 | J68: 157 | K68: %

Sheet Hoja1
B1: vi | D1: gmm
A2: edu | B2: 3 | C2: 60000
A3: amin | B3: 2 | C3: 50000
A4: pau | B4: 1 | C4: 20000
A5: carlos | B5: 2 | C5: 40000 | D5: 1 | E5: 20 | G5: =16000/1.03 -> 15533.981
A6: moni | B6: 3 | C6: 45000
A7: rafa | B7: 3 | C7: 60000
G10: x | H10: 100
G11: 16000 | H11: 30

Sheet Hoja3
E4: 1 | F4: 2020 | G4: 33 | H4: 550000 | I4: 13070 | J4: 13070 | K4: 0 | L4: 0 | M4: %
E5: 2 | F5: 2021 | G5: 34 | H5: 550000 | I5: 13070 | J5: 26140 | K5: 0 | L5: 0 | M5: %
E6: 3 | F6: 2022 | G6: 35 | H6: 550000 | I6: 13070 | J6: 39210 | K6: 13987 | L6: 36 | M6: %
E7: 4 | F7: 2023 | G7: 36 | H7: 550000 | I7: 13070 | J7: 52280 | K7: 21868 | L7: 42 | M7: %
E8: 5 | F8: 2024 | G8: 37 | H8: 550000 | I8: 13070 | J8: 65350 | K8: 30388 | L8: 46 | M8: %
E9: 6 | F9: 2025 | G9: 38 | H9: 550000 | I9: 13070 | J9: 78420 | K9: 39545 | L9: 50 | M9: %
E10: 7 | F10: 2026 | G10: 39 | H10: 550000 | I10: 13070 | J10: 91490 | K10: 49418 | L10: 54 | M10: %
E11: 8 | F11: 2027 | G11: 40 | H11: 550000 | I11: 13070 | J11: 104559 | K11: 59994 | L11: 57 | M11: %
E12: 9 | F12: 2028 | G12: 41 | H12: 550000 | I12: 13070 | J12: 117629 | K12: 71324 | L12: 61 | M12: %
E13: 10 | F13: 2029 | G13: 42 | H13: 550000 | I13: 13070 | J13: 130699 | K13: 83435 | L13: 64 | M13: %
E14: 11 | F14: 2030 | G14: 43 | H14: 550000 | I14: 13070 | J14: 143769 | K14: 96371 | L14: 67 | M14: %
E15: 12 | F15: 2031 | G15: 44 | H15: 550000 | I15: 13070 | J15: 156839 | K15: 110160 | L15: 70 | M15: %
... E35: 32 | F35: 2051 | G35: 64 | H35: 550000 | I35: 13070 | J35: 418238 | K35: 550000 | L35: 132 | M35: %

Sheet Hoja4
E5: 22 | G5: 49
E6: 5000 | G6: 35000
F18: =49-22 -> 27 | I18: =14000000/27 -> 518518.52
G20: =(35000+5000)/2 -> 20000 | H20: =G20*F18 -> 540000
